Workbook

Sheet 📊 DASHBOARD
A1: CATS INSIGHTS | MEMBER PROGRESS & WORKSHOP TRACKER
A2: President: Jason | Publication: CATS Insights | Academic Year: 2025–2026
B4: TOTAL MEMBERS | E4: SESSIONS COMPLETED | H4: AVG ATTENDANCE RATE | K4: AVG TEST SCORE IMPROVEMENT
B6: ='👥 MEMBER REGISTRY'!C2 -> 23 | E6: ='📅 SESSION LOG'!B2 -> 14 | H6: =DIVIDE('📅 SESSION LOG'!P4,'📅 SESSION LOG'!B2) -> 0.77542517 | K6: =IFERROR(AVERAGE('🧪 TEST SCORES'!H3:H100),0) -> 0.75833333
A9: HOW TO USE THIS WORKBOOK
A10: 📋 MEMBER REGISTRY → Add each member once. All other sheets reference this list.
A11: 📅 SESSION LOG → Log each workshop session (date, topic, room) before filling attendance.
A12: ✅ ATTENDANCE & ENGAGEMENT → Score every member 1-5 for participation, focus, and contribution.
A13: 🧪 TEST SCORES → Record Pre-Test and Post-Test scores (%) per session per member. | X13: r
A14: ✍️ WRITING QUALITY → Grade submitted work against PEEL / Three-Test / Turnitin criteria.
A15: 📈 INDIVIDUAL PROGRESS → Auto-calculated summary per member.
A16: 🏆 RSC EVIDENCE LOG → Paste specific evidence items (photos, captions, links) for RSC submission.
E20: MAINTENANCE NOTES
C23: Note from MDUC : The AVG Attendance rate code is broken, it's counting the "date" text, not the actual attendance rate, there's not
I24: please find a way to count attedance rate average only up to the amount of
K25: sessions, thanks aung | N25: (if you cant, tell duc)
C27: session code has been "patched" (im not fully sure if the code will break long term so keep watch please)

Sheet 👥 MEMBER REGISTRY
A1: MEMBER REGISTRY | Master Roster — All Active Members
B2: Active Member Count | C2: =COUNTIF(F4:F200,"Active") -> 23
A3: # | B3: Full Name | C3: Role / Title | D3: Primary Team / Department | E3: Secondary Team / Department | F3: Status | G3: School Year / Age | H3: Email / Teams Handle | I3: Notes (Personal Development Goals)
A4: 1 | B4: Oleksandr Boyko | C4: Vice President | D4: Leadership | E4: Writer | F4: Active | G4: Year 12 | H4: monkeydeluffy259@gmail.com
A5: 2 | B5: Hryhorii Suprun (Grisha) | C5: Lead Editor | D5: Leadership | E5: Editor | F5: Active | G5: Year 12 | H5: catsinsights210@gmail.com
A6: 3 | B6: Cindy Dong | C6: Part Timer | D6: Part Timer | E6: Nothing Else | F6: Active | G6: Year 13 | H6: 08cindydong@gmail.com
A7: 4 | B7: Anna Sazonova | C7: Lead Editor | D7: Editor | E7: Nothing Else | F7: Active | G7: Year 12 | H7: strifeweoos@gmail.com
A8: 5 | B8: Abdulaziz | C8: Writer | D8: Writer | E8: Editor | F8: Active | G8: Year 12 | H8: abdulazizmaksumov1@gmail.com
A9: 6 | B9: Aygul | C9: Designer | D9: Designer | E9: Marketing | F9: Active | G9: Year 13 | H9: aygulh1709@gmail.com
A10: 7 | B10: Bao Tran Uong (Tory) | C10: Part Timer | D10: Part Timer | E10: Nothing Else | F10: Active | G10: Year 13 | H10: uongbaotran@gmail.com
A11: 8 | B11: Bianca Alexandra (Alex) | C11: Writer | D11: Writer | E11: Nothing Else | F11: Active | G11: Year 10 | H11: biancalexrodiaz@gmail.com
A12: 9 | B12: Daniel | C12: Editor | D12: Editor | E12: Nothing Else | F12: Active | G12: Year 13 | H12: ojodannybobo@gmail.com
A13: 10 | B13: Elif | C13: Writer | D13: Writer | E13: Marketing | F13: Active | G13: Year 12 | H13: elifsudeduru04@gmail.com
A14: 11 | B14: Eti | C14: Writer | D14: Writer | E14: Marketing | F14: Active | G14: Year 13 | H14: etiabasiumoren@gmail.com
A15: 12 | B15: Bao | C15: Mascot | D15: Nothing Else | E15: Nothing Else | F15: Active | G15: Year 12 | H15: Huugiabao366@gmail.com
... A26: 23 | B26: Aung | C26: Deputy Secretary | D26: Leadership | E26: Editor | F26: Active | G26: Year 12 | H26: aungkhantpyaet.27@gmail.com

Sheet 📅 SESSION LOG
A1: SESSION LOG | One Row Per Workshop / Event
A2: Total Sessions | B2: =COUNTA(A4:A200) -> 14
A3: Session ID | B3: Date | C3: Session Title / Topic | D3: Lesson Focus | E3: Workshop Type | F3: Duration (mins) | G3: Room / Venue | H3: Members Invited | I3: Members Attended | J3: Attendance Rate | K3: Key Learning Objectives | L3: Criteria Fufilled | M3: Evidence Captured (Links to Drive) | N3: Link to find resources and lesson if absent | O3: Session Lead Notes | P3: Total Attendance
A4: WE01 | B4: 46086 | C4: Writer Lesson 1 | D4: How to navigate the system efficiently | E4: Writers Course | F4: 35 | G4: Room 209 | H4: 13 | I4: 11 | J4: 0.85 | K4: What we do and how we do it How to navigate the system efficiently Understanding the production pipeline What research is Types of research How to start and find sources How to read a research paper efficiently | L4: Academic Development | M4: Photos + Work Samples | N4: Lesson 1 | O4: Not so strong engagement due to many of them being alredy informed about materials of the class; 2 members need follow-up | P4: =SUM(J4:J100) -> 10.855952
A5: E02 | B5: 46090 | C5: Writer's Lesson 2 | D5: Audience | E5: Writers Course | F5: 45 | G5: Room 209 | H5: 4 | I5: 3 | J5: =IFERROR(I5/H5,0) -> 0.75 | K5: Understand target audience when writing a research article | L5: Academic Development | M5: Video | N5: Lesson 2
A6: E03 | B6: 46092 | C6: Academic language | D6: Formal writing: how to sound like a scholar | E6: Writers Course | F6: 50 | G6: Room 303 | H6: 4 | I6: 3 | J6: =IFERROR(I6/H6,0) -> 0.75 | K6: Register & Academic language | L6: Academic Development | M6: Video + completed practical exercise | N6: Lesson 3 | O6: All members engaged with the task actively
A7: D01 | B7: 46086 | C7: Designer's Lesson 1 | D7: Article formatting | E7: Designers Course | F7: 55 | G7: Room 208 | H7: 6 | I7: 5 | J7: =IFERROR(I7/H7,0) -> 0.83333333 | K7: Format articles & design 101 | L7: Skills Building | M7: photos | N7: https://www.canva.com/design/DAG_64z4Yys/zpPwtoMJIgD2PasWzaxR0w/edit?utm_content=DAG_64z4Yys&utm_campaign=designshare&utm_medium=link2&utm_source=sharebutton | O7: Members were present in the room on time, lackluster participation
A8: W02 | B8: 46093 | C8: Writers Lesson 2 | D8: WRITING FOR THE RIGHT AUDIENCE | E8: Writers Course | F8: 60 | G8: Room 301 | H8: 7 | I8: 6 | J8: =IFERROR(I8/H8,0) -> 0.85714286 | K8: Understand target audience when writing a research article | L8: Academic Development | M8: Video + completed practical exercise | N8: Lesson 2 | O8: Lots of good engagement with the task, silent but focused and not distracted at all, very good at interactions
A9: W03 | B9: 46094 | C9: Writers Lesson 3 | D9: ACADEMIC VOICE AND REGISTER | E9: Writers Course | F9: 50 | G9: Conference | H9: 8 | I9: 4 | J9: =IFERROR(I9/H9,0) -> 0.5 | L9: Academic Development
A10: W/E04 | B10: 46096 | C10: Writers & Editors Lesson 4 | D10: Article formatting | E10: Writers Course | F10: 40 | G10: 601 | H10: 8 | I10: 5 | J10: =IFERROR(I10/H10,0) -> 0.625 | K10: Understand the general structue of a research article | L10: Academic Development | M10: Video | N10: https://www.canva.com/design/DAHCXDVud8o/0YouO_05IUqjuJgDctsnSA/edit?utm_content=DAHCXDVud8o&utm_campaign=designshare&utm_medium=link2&utm_source=sharebutton
A11: D02 | B11: 46093 | C11: Designer's Lesson 2 | D11: Poster | E11: Designers Course | F11: 50 | G11: Room 209 | H11: 6 | I11: 4 | J11: =IFERROR(I11/H11,0) -> 0.66666667 | K11: Poster design basics | L11: Skills Building | M11: Video | N11: https://www.canva.com/design/DAHDjsy2cAs/qTwejWc2sUXcsY8DUJ7-8A/edit?utm_content=DAHDjsy2cAs&utm_campaign=designshare&utm_medium=link2&utm_source=sharebutton | O11: Members were present relatively timely, listened n responded attentively
A12: E05 | B12: 46097 | C12: Editor's Lesson 5 | D12: Article Structure | E12: Editors Course | F12: 50 | G12: Room 209 | H12: 3 | I12: 2 | J12: =IFERROR(I12/H12,0) -> 0.66666667 | K12: Understand how to read a research article & understand DOI | L12: Academic Development | M12: Video | O12: Members were partially
A13: E06 | B13: 46099 | C13: Editor's Lesson 6 | D13: Research Methods | E13: Writers Course | F13: 50 | G13: Room 303 | H13: 3 | I13: 2 | J13: =IFERROR(I13/H13,0) -> 0.66666667 | K13: Organising, Comparing & Evaluating Evidence | L13: Academic Development | M13: Video | N13: Lesson 6 | O13: Members were on time, actively listening and engaging with the presenter
A14: W05 | B14: 46100 | C14: Writers Lesson 5 | D14: Research Foundations | E14: Writers Course | F14: 50 | G14: Room 209 | H14: 7 | I14: 6 | J14: =IFERROR(I14/H14,0) -> 0.85714286 | K14: Understand how to read a research articles & understand DOI | L14: Academic Development | M14: Video + exercise | N14: Lesson 5
A15: D03 | B15: 46100 | C15: Designer's Lesson3 | D15: Magazine | E15: Designers Course | F15: 45 | G15: Room 208 | H15: 6 | I15: 5 | J15: =IFERROR(I15/H15,0) -> 0.83333333 | K15: Magazine design basics & practical | L15: Skills Building | M15: Video | N15: https://www.canva.com/design/DAHEUv3EcOc/ChvbctEy0wsVKk5GrCGmrQ/edit?utm_content=DAHEUv3EcOc&utm_campaign=designshare&utm_medium=link2&utm_source=sharebutton | O15: Members were present in the room on time, lackluster participation
A16: E06 | B16: 46103 | C16: Editor's Lesson 6 | D16: Citation mastery | E16: Editors Course | F16: 40 | G16: online | H16: 2 | I16: 2 | J16: =IFERROR(I16/H16,0) -> 1 | K16: Understand how to create citation properly, and use citation generator | L16: Academic Development | M16: Video
A17: E09 | B17: 46106 | C17: Writers Lesson 9 | D17: Integrity, Editorial Pipeline and checking | E17: Writers Course | F17: 50 | G17: Room | H17: 2 | I17: 2 | J17: =IFERROR(I17/H17,0) -> 1 | K17: AI Detection, integrity, false positives, proof of authorship, writer's presubmission checklist, submission process and editorial pipeline | L17: Academic Development | M17: Video | N17: Lesson 9.pdf | O17: Members were active and asked questions and meaningfully engaged with lesson
J18: =IFERROR(I18/H18,0) -> 0
J19: =IFERROR(I19/H19,0) -> 0
J20: =IFERROR(I20/H20,0) -> 0
J21: =IFERROR(I21/H21,0) -> 0
J22: =IFERROR(I22/H22,0) -> 0
J23: =IFERROR(I23/H23,0) -> 0
J24: =IFERROR(I24/H24,0) -> 0
J25: =IFERROR(I25/H25,0) -> 0
J26: =IFERROR(I26/H26,0) -> 0
J27: =IFERROR(I27/H27,0) -> 0
J28: =IFERROR(I28/H28,0) -> 0
J29: =IFERROR(I29/H29,0) -> 0
... J200: =IFERROR(I200/H200,0) -> 0

Sheet ✅ ATTENDANCE & ENGAGEMENT
A1: ATTENDANCE & ENGAGEMENT | Per-Member, Per-Session Scoring (0 = Poor → 5 = Excellent)
A2: ⚠️ Engagement Score = Average of Participation (P), Focus (F), and Contribution (C) | Attitude = Effort, Collaboration, Responsiveness to Feedback
A3: Session ID | B3: Date | C3: Member Name | D3: Role | E3: Attended? (Y/N) | F3: Late? (Y/N) | G3: Participation Score (1–5) | H3: Focus / Concentration (1–5) | I3: Contribution Quality (1–5) | J3: Engagement Average | K3: Attitude & Effort (1–5) | L3: Qualitative Notes (Specific Observations) | M3: Follow-Up Required? | N3: Follow-Up Action
A4: WE01 | B4: 46086 | C4: Abdulaziz Maksumov | E4: Y | F4: N | J4: =IFERROR(AVERAGE(G4:I4),"")
C5: Anna Sazonova | E5: N | F5: N | J5: =IFERROR(AVERAGE(G5:I5),"")
C6: Aung Khant Pyaet | E6: Y | F6: N | J6: =IFERROR(AVERAGE(G6:I6),"")
C7: Bianca Alexandra | E7: Y | F7: N | J7: =IFERROR(AVERAGE(G7:I7),"")
C8: Daniel Pelumi Ojo | E8: Y | F8: N | J8: =IFERROR(AVERAGE(G8:I8),"")
C9: Elif Sude Duru | E9: Y | F9: N | J9: =IFERROR(AVERAGE(G9:I9),"")
C10: Eti Abasi Essien | E10: Y | F10: N | J10: =IFERROR(AVERAGE(G10:I10),"")
C11: Hryhorii Suprun | E11: N | F11: N | J11: =IFERROR(AVERAGE(G11:I11),"")
C12: Minsu Song | E12: Y | F12: N | J12: =IFERROR(AVERAGE(G12:I12),"")
C13: Phillip Dan Tinashe | E13: Y | F13: N | J13: =IFERROR(AVERAGE(G13:I13),"")
C14: Tawin Chinnawuth | E14: Y | F14: N | J14: =IFERROR(AVERAGE(G14:I14),"")
C15: Tomas Rama | E15: Y | F15: N | J15: =IFERROR(AVERAGE(G15:I15),"")
A17: D01 | B17: 46086 | C17: Aung Khant Pyaet | E17: N | F17: N | G17: 0 | H17: 0 | I17: 0 | J17: =AVERAGE(G17:I17) -> 0 | K17: 0 | L17: N/A
C18: Aygul | E18: Y | F18: N | G18: 4 | H18: 3 | I18: 4 | J18: =AVERAGE(G18:I18) -> 3.6666667 | K18: 3 | L18: Asked questions, listened well, misunderstood assignment
C19: Kateryna | E19: Y | F19: N | G19: 2 | H19: 3 | I19: 2 | J19: =AVERAGE(G19:I19) -> 2.3333333 | K19: 3 | L19: Little attention
C20: Minh Duc Le | E20: Y | F20: N | G20: 3 | H20: 3 | I20: 3 | J20: =AVERAGE(G20:I20) -> 3 | K20: 3 | L20: Preoccupied with IT issue
C21: Nurmuhammet | E21: Y | F21: N | G21: 3 | H21: 2 | I21: 3 | J21: =AVERAGE(G21:I21) -> 2.6666667 | K21: 3 | L21: Decent
C22: Tsk Lok Mok | E22: Y | F22: N | G22: 2 | H22: 2 | I22: 2 | J22: =AVERAGE(G22:I22) -> 2 | K22: 3 | L22: Very inattentive, played with a fidget, misunderstood assignment
A24: E02 | B24: 46090 | C24: Abdulaziz Maksumov | E24: Y | F24: N | G24: 3 | H24: 3 | I24: 3 | J24: =AVERAGE(G24:I24) -> 3 | L24: Very attentive
C25: Aung Khant Pyaet | E25: Y | F25: N | G25: 3 | H25: 3 | I25: 3 | J25: =AVERAGE(G25:I25) -> 3 | L25: Attentive to the lesson
C26: Daniel Pelumi Ojo | E26: Y | F26: N | G26: 3 | H26: 2 | I26: 3 | J26: =AVERAGE(G26:I26) -> 2.6666667 | L26: Did not focus at the presentation sometimes
C27: Tomas Rama | E27: N | F27: N | G27: 0 | H27: 0 | I27: 0 | J27: =AVERAGE(G27:I27) -> 0 | K27: 0 | L27: N/A | M27: No
A29: E03 | B29: 46092 | C29: Abdulaziz Maksumov | E29: N | F29: Y | G29: 0 | H29: 0 | I29: 0 | J29: =AVERAGE(G29:I29) -> 0 | K29: 0 | L29: N/A | M29: No
C30: Aung Khant Pyaet | E30: Y | F30: N | G30: 3 | H30: 3 | I30: 3 | J30: =AVERAGE(G30:I30) -> 3 | K30: 2 | L30: attentive to the completion of practical exercise
C31: Daniel Pelumi Ojo | E31: Y | F31: Y | G31: 2 | H31: 3 | I31: 3 | J31: =AVERAGE(G31:I31) -> 2.6666667 | K31: 3 | L31: asked few questions
C32: Tomas Rama | E32: N | F32: Y | G32: 0 | H32: 0 | I32: 0 | J32: =IFERROR(AVERAGE(G32:I32),"") -> 0 | K32: 0 | L32: N/A
A33: W02 | B33: 46093 | C33: Elif | E33: Y | F33: N | G33: 2 | H33: 4 | J33: =IFERROR(AVERAGE(G33:I33),"") -> 3 | K33: 3 | L33: attentive to the completion of practical exercise and to the lesson but not much engagement
C34: Bianca Alexandra (Alex) | E34: Y | F34: N | G34: 2 | H34: 4 | J34: =IFERROR(AVERAGE(G34:I34),"") -> 3 | K34: 3 | L34: attentive to the completion of practical exercise and to the lesson but not much engagement
C35: Hryhorii Suprun (Grisha) | E35: Y | F35: N | G35: 3 | H35: 3 | J35: =IFERROR(AVERAGE(G35:I35),"") -> 3 | K35: 3 | L35: attentive to the completion of practical exercise and to the lesson but not much engagement
C36: Nurmuhammet | E36: Y | F36: N | G36: 2 | H36: 3 | J36: =IFERROR(AVERAGE(G36:I36),"") -> 2.5 | K36: 3 | L36: attentive to the completion of practical exercise and to the lesson but not much engagement
C37: Abdulaziz Maksumov | E37: Y | F37: N | G37: 2 | H37: 3 | J37: =IFERROR(AVERAGE(G37:I37),"") -> 2.5 | K37: 3 | L37: attentive to the completion of practical exercise and to the lesson but not much engagement
C38: Anna Sazonova | E38: Y | F38: N | G38: 3 | H38: 3 | J38: =IFERROR(AVERAGE(G38:I38)," ") -> 3 | K38: 3 | L38: attentive to the completion of practical exercise and to the lesson but not much engagement
C39: Eti | E39: N | F39: Y | G39: 0 | H39: 0 | J39: =IFERROR(AVERAGE(G39:I39),"") -> 0 | K39: 0 | L39: N/A
A40: W03 | B40: 46094 | C40: Elif | E40: Y | F40: N | G40: 5 | H40: 5 | J40: =IFERROR(AVERAGE(G40:I40),"") -> 5 | K40: 4 | M40: No
C41: Bianca Alexandra (Alex) | E41: Y | F41: N | G41: 5 | H41: 5 | J41: =IFERROR(AVERAGE(G41:I41),"") -> 5 | K41: 4 | M41: No
C42: Hryhorii Suprun (Grisha) | E42: Y | F42: N | J42: =IFERROR(AVERAGE(G42:I42),"") | K42: 0 | M42: Yes
C43: Nurmuhammet | E43: Y | F43: N | G43: 0 | J43: =IFERROR(AVERAGE(G43:I43),"") -> 0 | K43: 0 | M43: Yes
...

Sheet 🧪 TEST SCORES
A1: TEST SCORES | Pre-Test vs Post-Test Assessment Record — Measures Learning Gain
A2: Score Improvement = Post-Test % − Pre-Test % | GREEN ≥ +10pp | AMBER +1 to +9pp | RED = No Gain
A3: Session ID | B3: Date | C3: Member Name | D3: Topic Assessed | E3: Test Type (MCQ/Written/Practical) | F3: Previous Test Score (Raw) | G3: Previous Test Max Marks | H3: Previous Test % | I3: Latest Test Score (Raw) | J3: Latest Test Max Marks | K3: Latest Test % | L3: Score Improvement | M3: RAG Status | N3: Marker Comments / Diagnostic Notes | O3: Weak Areas Identified | P3: Follow-Up Topic Needed
A4: S001 | B4: 2026-03-01 | C4: Alex | D4: Science Communication Principles | E4: MCQ | F4: 12 | G4: 20 | H4: =IFERROR(F4/G4,"") -> 0.6 | I4: 17 | J4: 20 | K4: =IFERROR(I4/J4,"") -> 0.85 | L4: =IFERROR(K4-H4,"") -> 0.25 | M4: =IFERROR(IF(L4>=0.1,"🟢 GREEN",IF(L4>0,"🟡 AMBER","🔴 RED")),"—") -> 🟢 GREEN | N4: Strong improvement on Level 2 framing | O4: Over-technical in pre-test | P4: Level 2 rewriting
A5: S001 | B5: 2026-03-01 | C5: Grisha | D5: Science Communication Principles | E5: MCQ | F5: 15 | G5: 20 | H5: =IFERROR(F5/G5,"") -> 0.75 | I5: 19 | J5: 20 | K5: =IFERROR(I5/J5,"") -> 0.95 | L5: =IFERROR(K5-H5,"") -> 0.2 | M5: =IFERROR(IF(L5>=0.1,"🟢 GREEN",IF(L5>0,"🟡 AMBER","🔴 RED")),"—") -> 🟢 GREEN | N5: Excellent; consistently accurate | O5: Minor: jargon control
A6: S001 | B6: 2026-03-01 | C6: Cindy | D6: Science Communication Principles | E6: MCQ | F6: 10 | G6: 20 | H6: =IFERROR(F6/G6,"") -> 0.5 | I6: 14 | J6: 20 | K6: =IFERROR(I6/J6,"") -> 0.7 | L6: =IFERROR(K6-H6,"") -> 0.2 | M6: =IFERROR(IF(L6>=0.1,"🟢 GREEN",IF(L6>0,"🟡 AMBER","🔴 RED")),"—") -> 🟢 GREEN | N6: Good progress; needs more practice | O6: Analogy generation weak | P6: Analogy workshop
A7: S003 | B7: 46090 | C7: Abdulaziz | D7: Level 2 writing | E7: Written | F7: None | G7: None | H7: =IFERROR(F7/G7,"") | I7: 15 | J7: 20 | K7: =IFERROR(I7/J7,"") -> 0.75 | L7: =IFERROR(K7-H7,"") -> 0.75 | M7: =IFERROR(IF(L7>=0.1,"🟢 GREEN",IF(L7>0,"🟡 AMBER","🔴 RED")),"—") -> 🟢 GREEN | N7: Overall, a good rewritten paragraph, including comprehensive contents to leve 2 audiences. However, a little deduction on the flow of narration and some niche vocabularies were used
A8: S003 | B8: 46090 | C8: Aung | D8: Level 2 writing | E8: Written | F8: None | G8: None | H8: =IFERROR(F8/G8,"") | I8: 18 | J8: 20 | K8: =IFERROR(I8/J8,"") -> 0.9 | L8: =IFERROR(K8-H8,"") -> 0.9 | M8: =IFERROR(IF(L8>=0.1,"🟢 GREEN",IF(L8>0,"🟡 AMBER","🔴 RED")),"—") -> 🟢 GREEN | N8: Very good rewritten paragraph. No point to improve in terms of contents, but the paragraph is one sentence.
A9: S003 | B9: 46090 | C9: Daniel | D9: Level 2 writing | E9: Written | F9: None | G9: None | H9: =IFERROR(F9/G9,"") | I9: 11 | J9: 20 | K9: =IFERROR(I9/J9,"") -> 0.55 | L9: =IFERROR(K9-H9,"") -> 0.55 | M9: =IFERROR(IF(L9>=0.1,"🟢 GREEN",IF(L9>0,"🟡 AMBER","🔴 RED")),"—") -> 🟢 GREEN | N9: Well rewritten. However, some jargons were still used, such as "LDL", "antioxidants", wihch may still be a bit difficult to engage with level 2 audience.
A10: W02 | B10: 46093 | C10: Elif | D10: Level 2 writing | E10: Written | F10: None | G10: None | H10: =IFERROR(F10/G10,"") | I10: 16 | J10: 20 | K10: =IFERROR(I10/J10,"") -> 0.8 | L10: =IFERROR(K10-H10,"") -> 0.8 | M10: =IFERROR(IF(L10>=0.1,"🟢 GREEN",IF(L10>0,"🟡 AMBER","🔴 RED")),"—") -> 🟢 GREEN | N10: You made an excellent strategic decision to completely translate complex jargon (like "endothelial dysfunction" and "atherogenesis") into plain English rather than just defining them. However, a major grammatical error, recurring formatting issues, and the complete lack of citations brought your score down significantly.
A11: W02 | B11: 46093 | C11: Bianca Alexandra (Alex) | D11: Level 2 writing | E11: Written | F11: None | G11: None | H11: =IFERROR(F11/G11,"") | I11: 14 | J11: 20 | K11: =IFERROR(I11/J11,"") -> 0.7 | L11: =IFERROR(K11-H11,"") -> 0.7 | M11: =IFERROR(IF(L11>=0.1,"🟢 GREEN",IF(L11>0,"🟡 AMBER","🔴 RED")),"—") -> 🟢 GREEN | N11: You have demonstrated a strong ability to translate Expert (Level 1) density into an Educated Non-Specialist (Level 2) format while retaining scientific precision. However, there are a few formatting and structural rules mandated by the CATS Insights curriculum that you missed.
A12: W02 | B12: 46093 | C12: Hryhorii Suprun (Grisha) | D12: Level 2 writing | E12: Written | F12: None | G12: None | H12: =IFERROR(F12/G12,"") | I12: 12 | J12: 20 | K12: =IFERROR(I12/J12,"") -> 0.6 | L12: =IFERROR(K12-H12,"") -> 0.6 | M12: =IFERROR(IF(L12>=0.1,"🟢 GREEN",IF(L12>0,"🟡 AMBER","🔴 RED")),"—") -> 🟢 GREEN | N12: You made a massive leap forward by successfully integrating your in-text citations and linking them to a highly credible bibliography. However, in your effort to define every technical term, you created a single, incredibly dense run-on sentence that severely impacts readability.
A13: W02 | B13: 46093 | C13: Nurmuhammet | D13: Level 2 writing | E13: Written | F13: None | G13: None | H13: =IFERROR(F13/G13,"") | I13: 5 | J13: 20 | K13: =IFERROR(I13/J13,"") -> 0.25 | L13: =IFERROR(K13-H13,"") -> 0.25 | M13: =IFERROR(IF(L13>=0.1,"🟢 GREEN",IF(L13>0,"🟡 AMBER","🔴 RED")),"—") -> 🟢 GREEN | N13: While your attempt focused heavily on making the text accessible, you overshot the target and landed in Level 3 (General Public) territory, sacrificing the academic standard required by CATS Insights. Additionally, severe grammatical errors and a complete lack of sources significantly impacted your score.
A14: W02 | B14: 46093 | C14: Abdulaziz Maksumov | D14: Level 2 writing | E14: Written | F14: None | G14: None | H14: =IFERROR(F14/G14,"") | I14: 11 | J14: 20 | K14: =IFERROR(I14/J14,"") -> 0.55 | L14: =IFERROR(K14-H14,"") -> 0.55 | M14: =IFERROR(IF(L14>=0.1,"🟢 GREEN",IF(L14>0,"🟡 AMBER","🔴 RED")),"—") -> 🟢 GREEN | N14: While you successfully improved your sentence length and structure, a massive factual error and the complete omission of your sources severely impacted your score.
A15: W02 | B15: 46093 | C15: Anna Sazonova | D15: Level 2 writing | E15: Written | F15: None | G15: None | H15: =IFERROR(F15/G15,"") | I15: 8 | J15: 20 | K15: =IFERROR(I15/J15,"") -> 0.4 | L15: =IFERROR(K15-H15,"") -> 0.4 | M15: =IFERROR(IF(L15>=0.1,"🟢 GREEN",IF(L15>0,"🟡 AMBER","🔴 RED")),"—") -> 🟢 GREEN | N15: While you successfully retained the scientific precision of the original Expert (Level 1) text, this draft fails several structural and formatting rules mandated by the curriculum, particularly regarding how definitions and citations are supposed to be integrated into the text.
A16: W03 | B16: 46094 | C16: Elif | D16: ACADEMIC VOICE AND REGISTER | E16: Written | F16: None | G16: None | H16: =IFERROR(F16/G16,"") | I16: 13 | J16: 20 | K16: =IFERROR(I16/J16,"") -> 0.65 | L16: =IFERROR(K16-H16,"") -> 0.65 | M16: =IFERROR(IF(L16>=0.1,"🟢 GREEN",IF(L16>0,"🟡 AMBER","🔴 RED")),"—") -> 🟢 GREEN | N16: Strong academic structure and voice, but penalised for comma splices and excessive sentence length.
A17: W03 | B17: 46094 | C17: Bianca Alexandra (Alex) | D17: ACADEMIC VOICE AND REGISTER | E17: Written | F17: None | G17: None | H17: =IFERROR(F17/G17,"") | I17: 14 | J17: 20 | K17: =IFERROR(I17/J17,"") -> 0.7 | L17: =IFERROR(K17-H17,"") -> 0.7 | M17: =IFERROR(IF(L17>=0.1,"🟢 GREEN",IF(L17>0,"🟡 AMBER","🔴 RED")),"—") -> 🟢 GREEN | N17: Excellent objective tone and hedging, but missed the top tier by omitting the required jargon-definition formatting.
A18: W03 | B18: 46094 | C18: Hryhorii Suprun (Grisha) | D18: ACADEMIC VOICE AND REGISTER | E18: Written | F18: None | G18: None | J18: 20 | K18: =IFERROR(I18/J18,"") -> 0 | L18: =IFERROR(K18-H18,"") -> 0 | M18: =IFERROR(IF(L18>=0.1,"🟢 GREEN",IF(L18>0,"🟡 AMBER","🔴 RED")),"—") -> 🔴 RED
A19: W03 | B19: 46094 | C19: Nurmuhammet | D19: ACADEMIC VOICE AND REGISTER | E19: Written | F19: None | G19: None | H19: =IFERROR(F19/G19,"") | I19: 8 | J19: 20 | K19: =IFERROR(I19/J19,"") -> 0.4 | L19: =IFERROR(K19-H19,"") -> 0.4 | M19: =IFERROR(IF(L19>=0.1,"🟢 GREEN",IF(L19>0,"🟡 AMBER","🔴 RED")),"—") -> 🟢 GREEN | N19: Good logical progression, but undermined by informal "student" phrasing and subject-verb agreement errors.
A20: W03 | B20: 46094 | C20: Abdulaziz Maksumov | D20: ACADEMIC VOICE AND REGISTER | E20: Written | F20: None | G20: None | H20: =IFERROR(F20/G20,"") | J20: 20 | K20: =IFERROR(I20/J20,"") -> 0 | L20: =IFERROR(K20-H20,"") -> 0 | M20: =IFERROR(IF(L20>=0.1,"🟢 GREEN",IF(L20>0,"🟡 AMBER","🔴 RED")),"—") -> 🔴 RED
A21: W03 | B21: 46094 | C21: Eti | D21: ACADEMIC VOICE AND REGISTER | E21: Written | F21: None | G21: None | H21: =IFERROR(F21/G21,"") | J21: 20 | K21: =IFERROR(I21/J21,"") -> 0 | L21: =IFERROR(K21-H21,"") -> 0 | M21: =IFERROR(IF(L21>=0.1,"🟢 GREEN",IF(L21>0,"🟡 AMBER","🔴 RED")),"—") -> 🔴 RED
A22: W03 | B22: 46094 | C22: Minh Duc Le | D22: ACADEMIC VOICE AND REGISTER | E22: Written | F22: None | G22: None | H22: =IFERROR(F22/G22,"") | J22: 20 | K22: =IFERROR(I22/J22,"") -> 0 | L22: =IFERROR(K22-H22,"") -> 0 | M22: =IFERROR(IF(L22>=0.1,"🟢 GREEN",IF(L22>0,"🟡 AMBER","🔴 RED")),"—") -> 🔴 RED
H23: =IFERROR(F23/G23,"") | K23: =IFERROR(I23/J23,"") | L23: =IFERROR(K23-H23,"") -> 0 | M23: =IFERROR(IF(L23>=0.1,"🟢 GREEN",IF(L23>0,"🟡 AMBER","🔴 RED")),"—") -> 🔴 RED
A24: W/E04 | B24: 46096 | C24: Abdulaziz Maksumov | D24: Article Structure | E24: Written | H24: =IFERROR(F24/G24,"") | I24: 13 | J24: 20 | K24: =IFERROR(I24/J24,"") -> 0.65 | L24: =IFERROR(K24-H24,"") -> 0.65 | M24: =IFERROR(IF(L24>=0.1,"🟢 GREEN",IF(L24>0,"🟡 AMBER","🔴 RED")),"—") -> 🟢 GREEN | N24: Able to strongly link the PEEL structure into the given article, with comprehensive summary and abstract, though it is not entirely necessary to indicate the PEEL into the structure. Headings were also not given
A25: W/E04 | B25: 46096 | C25: Aung Khant Pyaet | D25: Article Structure | E25: Written | H25: =IFERROR(F25/G25,"") | I25: 17 | J25: 20 | K25: =IFERROR(I25/J25,"") -> 0.85 | L25: =IFERROR(K25-H25,"") -> 0.85 | M25: =IFERROR(IF(L25>=0.1,"🟢 GREEN",IF(L25>0,"🟡 AMBER","🔴 RED")),"—") -> 🟢 GREEN | N25: Well written and comprehensive article, with inclusion of headings, abstract and rearranged article
A26: W/E04 | B26: 46096 | C26: Nurmuhammet Charryarov | D26: Article Structure | E26: Written | H26: =IFERROR(F26/G26,"") | J26: 20 | K26: =IFERROR(I26/J26,"") -> 0 | L26: =IFERROR(K26-H26,"") -> 0 | M26: =IFERROR(IF(L26>=0.1,"🟢 GREEN",IF(L26>0,"🟡 AMBER","🔴 RED")),"—") -> 🔴 RED
A27: W/E04 | B27: 46096 | C27: Anna Sazonova | D27: Article Structure | E27: Written | H27: =IFERROR(F27/G27,"") | I27: 17 | J27: 20 | K27: =IFERROR(I27/J27,"") -> 0.85 | L27: =IFERROR(K27-H27,"") -> 0.85 | M27: =IFERROR(IF(L27>=0.1,"🟢 GREEN",IF(L27>0,"🟡 AMBER","🔴 RED")),"—") -> 🟢 GREEN | N27: Although evident that the article may already be in PEEL structure, Anna was able to create appropriate headings in accordance to the contents of each paragraph
A28: W/E04 | B28: 46096 | C28: Bianca Alexandra (Alex) | D28: Article Structure | E28: Written | H28: =IFERROR(F28/G28,"") | I28: 15 | J28: 20 | K28: =IFERROR(I28/J28,"") -> 0.75 | L28: =IFERROR(K28-H28,"") -> 0.75 | M28: =IFERROR(IF(L28>=0.1,"🟢 GREEN",IF(L28>0,"🟡 AMBER","🔴 RED")),"—") -> 🟢 GREEN | N28: Greatly written abstract and headers
A29: W/E04 | B29: 46096 | C29: Hryhorii Suprun (Grisha) | D29: Article Structure | E29: Written | H29: =IFERROR(F29/G29,"") | I29: 15 | J29: 20 | K29: =IFERROR(I29/J29,"") -> 0.75 | L29: =IFERROR(K29-H29,"") -> 0.75 | M29: =IFERROR(IF(L29>=0.1,"🟢 GREEN",IF(L29>0,"🟡 AMBER","🔴 RED")),"—") -> 🟢 GREEN | N29: Well written headings, though there is an incomplete header
A30: W/E04 | B30: 46096 | C30: Daniel Pelumi Ojo | D30: Article Structure | E30: Written | H30: =IFERROR(F30/G30,"") | J30: 20 | K30: =IFERROR(I30/J30,"") -> 0 | L30: =IFERROR(K30-H30,"") -> 0 | M30: =IFERROR(IF(L30>=0.1,"🟢 GREEN",IF(L30>0,"🟡 AMBER","🔴 RED")),"—") -> 🔴 RED
H31: =IFERROR(F31/G31,"") | K31: =IFERROR(I31/J31,"") | L31: =IFERROR(K31-H31,"") -> 0 | M31: =IFERROR(IF(L31>=0.1,"🟢 GREEN",IF(L31>0,"🟡 AMBER","🔴 RED")),"—") -> 🔴 RED
A32: E05 | B32: 46097 | C32: Aung Khant Pyaet | D32: Research Foundations | E32: Written | F32: 17 | G32: 20 | H32: =IFERROR(F32/G32,"") -> 0.85 | I32: 20 | J32: 20 | K32: =IFERROR(I32/J32,"") -> 1 | L32: =IFERROR(K32-H32,"") -> 0.15 | M32: =IFERROR(IF(L32>=0.1,"🟢 GREEN",IF(L32>0,"🟡 AMBER","🔴 RED")),"—") -> 🟢 GREEN | N32: Very simple work, which has been done asppropriately
A33: E05 | B33: 46097 | C33: Daniel Pelumi Ojo | D33: Research Foundations | E33: Written | H33: =IFERROR(F33/G33,"") | I33: 17 | J33: 20 | K33: =IFERROR(I33/J33,"") -> 0.85 | L33: =IFERROR(K33-H33,"") -> 0.85 | M33: =IFERROR(IF(L33>=0.1,"🟢 GREEN",IF(L33>0,"🟡 AMBER","🔴 RED")),"—") -> 🟢 GREEN | N33: Able to identify necessary findings, but the summary needs to get rid of pronouns such as "They" as it is not an element in a research literarture review
H34: =IFERROR(F34/G34,"") | K34: =IFERROR(I34/J34,"") | L34: =IFERROR(K34-H34,"") -> 0 | M34: =IFERROR(IF(L34>=0.1,"🟢 GREEN",IF(L34>0,"🟡 AMBER","🔴 RED")),"—") -> 🔴 RED
A35: E06 | B35: 46099 | C35: Aung khant Pyaet | D35: Research Methods | E35: Written | F35: 20 | G35: 20 | H35: =IFERROR(F35/G35,"") -> 1 | I35: 20 | J35: 20 | K35: =IFERROR(I35/J35,"") -> 1 | L35: =IFERROR(K35-H35,"") -> 0 | M35: =IFERROR(IF(L35>=0.1,"🟢 GREEN",IF(L35>0,"🟡 AMBER","🔴 RED")),"—") -> 🔴 RED
A36: E06 | B36: 46099 | C36: Daniel pelumi Ojo | D36: Research Methods | E36: Written | F36: 17 | G36: 20 | H36: =IFERROR(F36/G36,"") -> 0.85 | J36: 20 | K36: =IFERROR(I36/J36,"") -> 0 | L36: =IFERROR(K36-H36,"") -> -0.85 | M36: =IFERROR(IF(L36>=0.1,"🟢 GREEN",IF(L36>0,"🟡 AMBER","🔴 RED")),"—") -> 🔴 RED
H37: =IFERROR(F37/G37,"") | I37: 18 | K37: =IFERROR(I37/J37,"") | L37: =IFERROR(K37-H37,"") -> 0 | M37: =IFERROR(IF(L37>=0.1,"🟢 GREEN",IF(L37>0,"🟡 AMBER","🔴 RED")),"—") -> 🔴 RED
H38: =IFERROR(F38/G38,"") | I38: 18 | K38: =IFERROR(I38/J38,"") | L38: =IFERROR(K38-H38,"") -> 0 | M38: =IFERROR(IF(L38>=0.1,"🟢 GREEN",IF(L38>0,"🟡 AMBER","🔴 RED")),"—") -> 🔴 RED
H39: =IFERROR(F39/G39,"") | I39: 18 | K39: =IFERROR(I39/J39,"") | L39: =IFERROR(K39-H39,"") -> 0 | M39: =IFERROR(IF(L39>=0.1,"🟢 GREEN",IF(L39>0,"🟡 AMBER","🔴 RED")),"—") -> 🔴 RED
H40: =IFERROR(F40/G40,"") | I40: 18 | K40: =IFERROR(I40/J40,"") | L40: =IFERROR(K40-H40,"") -> 0 | M40: =IFERROR(IF(L40>=0.1,"🟢 GREEN",IF(L40>0,"🟡 AMBER","🔴 RED")),"—") -> 🔴 RED
...

Sheet Mistakes
A20: Due to the high pace of production of the lessons for the writers course, a lot of people were involved in the process to ensure speed and quality. However, with those benefits also came some complications in communication. Consequently, a problem occurred with one of the editors. After completion, the lessons were reviewed and some final corrections were made; however, the editor responsible for the correction of Lesson 7 of the writers course forgot to submit the final draft to the Google Drive. This led to the presenter having a flawed and short presentation during Editor’s Lesson 7. The problem was spotted immediately after the lesson and was fixed. All the participants were informed about the mistake and invited to attend the respective workshop again. Furthermore, since the mistake was made by the leadership team, it was unfair towards the participants to make it mandatory to attend the session again, so for those who did not attend due to personal reasons, no penalty was introduced; rather, a personal, much more concise session was created to cover the lost content. Moreover, the materials for the class were introduced in written form as well. So, despite facing the problem, we managed to mitigate the consequences and created an efficient and fair solution, demonstrating resilience and a high level of problem-solving skills.

Sheet ✍️ WRITING QUALITY
A1: WRITING QUALITY | Article & Assignment Assessment Log — CATS Insights Editorial Standards
A2: All scores /10 | Turnitin <15% | GPTZero: Human | Oxford citation format | PEEL structure enforced
A3: Sub ID | B3: Date Submitted | C3: Member Name | D3: Article / Assignment Title | E3: Stage (Draft 1/2/Final) | F3: Word Count | G3: PEEL Structure (/10) | H3: Argument Clarity (/10) | I3: Scientific Accuracy (/10) | J3: Level 2 Tone (/10) | K3: Citation Compliance (/10) | L3: Turnitin % (<15% = Pass) | M3: GPTZero Result | N3: Overall Quality Score | O3: QA Gate Status | P3: Editor Feedback Summary | Q3: Revisions Required | R3: Revision Deadline
N4: =IFERROR(AVERAGE(G4:K4),"")
N5: =IFERROR(AVERAGE(G5:K5),"")
N6: =IFERROR(AVERAGE(G6:K6),"")
N7: =IFERROR(AVERAGE(G7:K7),"")
N8: =IFERROR(AVERAGE(G8:K8),"")
N9: =IFERROR(AVERAGE(G9:K9),"")
N10: =IFERROR(AVERAGE(G10:K10),"")
N11: =IFERROR(AVERAGE(G11:K11),"")
N12: =IFERROR(AVERAGE(G12:K12),"")
N13: =IFERROR(AVERAGE(G13:K13),"")
N14: =IFERROR(AVERAGE(G14:K14),"")
N15: =IFERROR(AVERAGE(G15:K15),"")
... N200: =IFERROR(AVERAGE(G200:K200),"")

Sheet 📈 INDIVIDUAL PROGRESS
A1: INDIVIDUAL PROGRESS SUMMARY | Auto-aggregated per Member
A2: ⚡ All calculated columns update automatically as you log data in other sheets
A3: # | B3: Member Name | C3: Role | D3: Sessions Attended | E3: Attendance Rate | F3: Avg Engagement Score | G3: Avg Pre-Test % | H3: Avg Post-Test % | I3: Avg Test Improvement | J3: Avg Writing Quality Score | K3: Articles / Assignments Submitted | L3: Articles Passed QA | M3: Overall Progress Rating
A4: 1 | B4: Alex [Deputy VP] | C4: ='👥 MEMBER REGISTRY'!C4 -> Vice President | D4: =COUNTIFS('✅ ATTENDANCE & ENGAGEMENT'!C$4:C$500,B4,'✅ ATTENDANCE & ENGAGEMENT'!E$4:E$500,"Y") -> 0 | E4: =IFERROR(D4/'📅 SESSION LOG'!$B$2,"") -> 0 | F4: =IFERROR(AVERAGEIF('✅ ATTENDANCE & ENGAGEMENT'!C$4:C$500,B4,'✅ ATTENDANCE & ENGAGEMENT'!J$4:J$500),"") | G4: =IFERROR(AVERAGEIF('🧪 TEST SCORES'!C$4:C$500,B4,'🧪 TEST SCORES'!H$4:H$500),"") | H4: =IFERROR(AVERAGEIF('🧪 TEST SCORES'!C$4:C$500,B4,'🧪 TEST SCORES'!K$4:K$500),"") | I4: =IFERROR(H4-G4,"") -> 0 | J4: =IFERROR(AVERAGEIF('✍️ WRITING QUALITY'!C$4:C$500,B4,'✍️ WRITING QUALITY'!N$4:N$500),"") | K4: =COUNTIF('✍️ WRITING QUALITY'!C$4:C$500,B4) -> 0 | L4: =COUNTIFS('✍️ WRITING QUALITY'!C$4:C$500,B4,'✍️ WRITING QUALITY'!O$4:O$500,"🟢 PASS") -> 0 | M4: =IFERROR(IF(AVERAGE(IFERROR(F4,0),IFERROR(H4*10,0),IFERROR(J4,0))>=8,"🟢 Excellent",IF(AVERAGE(IFERROR(F4,0),IFERROR(H4*10,0),IFERROR(J4,0))>=6,"🟡 Good","🔴 Needs Support")),"—") -> 🔴 Needs Support
A5: 2 | B5: Grisha | C5: ='👥 MEMBER REGISTRY'!C5 -> Lead Editor | D5: =COUNTIFS('✅ ATTENDANCE & ENGAGEMENT'!C$4:C$500,B5,'✅ ATTENDANCE & ENGAGEMENT'!E$4:E$500,"Y") -> 0 | E5: =IFERROR(D5/'📅 SESSION LOG'!$B$2,"") -> 0 | F5: =IFERROR(AVERAGEIF('✅ ATTENDANCE & ENGAGEMENT'!C$4:C$500,B5,'✅ ATTENDANCE & ENGAGEMENT'!J$4:J$500),"") | G5: =IFERROR(AVERAGEIF('🧪 TEST SCORES'!C$4:C$500,B5,'🧪 TEST SCORES'!H$4:H$500),"") -> 0.75 | H5: =IFERROR(AVERAGEIF('🧪 TEST SCORES'!C$4:C$500,B5,'🧪 TEST SCORES'!K$4:K$500),"") -> 0.95 | I5: =IFERROR(H5-G5,"") -> 0.2 | J5: =IFERROR(AVERAGEIF('✍️ WRITING QUALITY'!C$4:C$500,B5,'✍️ WRITING QUALITY'!N$4:N$500),"") | K5: =COUNTIF('✍️ WRITING QUALITY'!C$4:C$500,B5) -> 0 | L5: =COUNTIFS('✍️ WRITING QUALITY'!C$4:C$500,B5,'✍️ WRITING QUALITY'!O$4:O$500,"🟢 PASS") -> 0 | M5: =IFERROR(IF(AVERAGE(IFERROR(F5,0),IFERROR(H5*10,0),IFERROR(J5,0))>=8,"🟢 Excellent",IF(AVERAGE(IFERROR(F5,0),IFERROR(H5*10,0),IFERROR(J5,0))>=6,"🟡 Good","🔴 Needs Support")),"—") -> 🟢 Excellent
A6: 3 | B6: Cindy | C6: ='👥 MEMBER REGISTRY'!C6 -> Part Timer | D6: =COUNTIFS('✅ ATTENDANCE & ENGAGEMENT'!C$4:C$500,B6,'✅ ATTENDANCE & ENGAGEMENT'!E$4:E$500,"Y") -> 0 | E6: =IFERROR(D6/'📅 SESSION LOG'!$B$2,"") -> 0 | F6: =IFERROR(AVERAGEIF('✅ ATTENDANCE & ENGAGEMENT'!C$4:C$500,B6,'✅ ATTENDANCE & ENGAGEMENT'!J$4:J$500),"") | G6: =IFERROR(AVERAGEIF('🧪 TEST SCORES'!C$4:C$500,B6,'🧪 TEST SCORES'!H$4:H$500),"") -> 0.5 | H6: =IFERROR(AVERAGEIF('🧪 TEST SCORES'!C$4:C$500,B6,'🧪 TEST SCORES'!K$4:K$500),"") -> 0.7 | I6: =IFERROR(H6-G6,"") -> 0.2 | J6: =IFERROR(AVERAGEIF('✍️ WRITING QUALITY'!C$4:C$500,B6,'✍️ WRITING QUALITY'!N$4:N$500),"") | K6: =COUNTIF('✍️ WRITING QUALITY'!C$4:C$500,B6) -> 0 | L6: =COUNTIFS('✍️ WRITING QUALITY'!C$4:C$500,B6,'✍️ WRITING QUALITY'!O$4:O$500,"🟢 PASS") -> 0 | M6: =IFERROR(IF(AVERAGE(IFERROR(F6,0),IFERROR(H6*10,0),IFERROR(J6,0))>=8,"🟢 Excellent",IF(AVERAGE(IFERROR(F6,0),IFERROR(H6*10,0),IFERROR(J6,0))>=6,"🟡 Good","🔴 Needs Support")),"—") -> 🟡 Good
A7: 4 | B7: Member 4 | C7: ='👥 MEMBER REGISTRY'!C7 -> Lead Editor | D7: =COUNTIFS('✅ ATTENDANCE & ENGAGEMENT'!C$4:C$500,B7,'✅ ATTENDANCE & ENGAGEMENT'!E$4:E$500,"Y") -> 0 | E7: =IFERROR(D7/'📅 SESSION LOG'!$B$2,"") -> 0 | F7: =IFERROR(AVERAGEIF('✅ ATTENDANCE & ENGAGEMENT'!C$4:C$500,B7,'✅ ATTENDANCE & ENGAGEMENT'!J$4:J$500),"") | G7: =IFERROR(AVERAGEIF('🧪 TEST SCORES'!C$4:C$500,B7,'🧪 TEST SCORES'!H$4:H$500),"") | H7: =IFERROR(AVERAGEIF('🧪 TEST SCORES'!C$4:C$500,B7,'🧪 TEST SCORES'!K$4:K$500),"") | I7: =IFERROR(H7-G7,"") -> 0 | J7: =IFERROR(AVERAGEIF('✍️ WRITING QUALITY'!C$4:C$500,B7,'✍️ WRITING QUALITY'!N$4:N$500),"") | K7: =COUNTIF('✍️ WRITING QUALITY'!C$4:C$500,B7) -> 0 | L7: =COUNTIFS('✍️ WRITING QUALITY'!C$4:C$500,B7,'✍️ WRITING QUALITY'!O$4:O$500,"🟢 PASS") -> 0 | M7: =IFERROR(IF(AVERAGE(IFERROR(F7,0),IFERROR(H7*10,0),IFERROR(J7,0))>=8,"🟢 Excellent",IF(AVERAGE(IFERROR(F7,0),IFERROR(H7*10,0),IFERROR(J7,0))>=6,"🟡 Good","🔴 Needs Support")),"—") -> 🔴 Needs Support
A8: 5 | B8: Member 5 | C8: ='👥 MEMBER REGISTRY'!C8 -> Writer | D8: =COUNTIFS('✅ ATTENDANCE & ENGAGEMENT'!C$4:C$500,B8,'✅ ATTENDANCE & ENGAGEMENT'!E$4:E$500,"Y") -> 0 | E8: =IFERROR(D8/'📅 SESSION LOG'!$B$2,"") -> 0 | F8: =IFERROR(AVERAGEIF('✅ ATTENDANCE & ENGAGEMENT'!C$4:C$500,B8,'✅ ATTENDANCE & ENGAGEMENT'!J$4:J$500),"") | G8: =IFERROR(AVERAGEIF('🧪 TEST SCORES'!C$4:C$500,B8,'🧪 TEST SCORES'!H$4:H$500),"") | H8: =IFERROR(AVERAGEIF('🧪 TEST SCORES'!C$4:C$500,B8,'🧪 TEST SCORES'!K$4:K$500),"") | I8: =IFERROR(H8-G8,"") -> 0 | J8: =IFERROR(AVERAGEIF('✍️ WRITING QUALITY'!C$4:C$500,B8,'✍️ WRITING QUALITY'!N$4:N$500),"") | K8: =COUNTIF('✍️ WRITING QUALITY'!C$4:C$500,B8) -> 0 | L8: =COUNTIFS('✍️ WRITING QUALITY'!C$4:C$500,B8,'✍️ WRITING QUALITY'!O$4:O$500,"🟢 PASS") -> 0 | M8: =IFERROR(IF(AVERAGE(IFERROR(F8,0),IFERROR(H8*10,0),IFERROR(J8,0))>=8,"🟢 Excellent",IF(AVERAGE(IFERROR(F8,0),IFERROR(H8*10,0),IFERROR(J8,0))>=6,"🟡 Good","🔴 Needs Support")),"—") -> 🔴 Needs Support

Sheet 🏆 RSC EVIDENCE LOG
A1: RSC KENT YOUNG CHEMIST AWARD — EVIDENCE LOG | Submission Deadline: 31 March 2026
A2: Each row = ONE discrete piece of evidence. Link to file / screenshot. Map to RSC criterion. Quantity + quality matters.
A3: Ref # | B3: Date | C3: Evidence Title / Description | D3: RSC Criterion Category | E3: Evidence Type | F3: Chemistry Content (Specific Topic) | G3: Audience / Reach (# people) | H3: Measurable Outcome | I3: File Path / URL / Screenshot | J3: Quality Rating (1–5) | K3: Verified by (President sign-off) | L3: Additional Context Notes
A4: E001 | B4: 2026-03-01 | C4: Writing Chemistry for Non-Chemists — Workshop Delivery | D4: Mentoring & Teaching | E4: Workshop Delivery | F4: 3-Level Science Communication Framework | G4: 9 | H4: 9 members attended; avg post-test improvement +35% | I4: Google Drive > RSC Evidence > S001_Workshop | J4: 5 | K4: Jason | L4: First formal workshop; pre/post test administered
A5: E002 | B5: 2026-03-01 | C5: Instagram Carousel — White Cliffs of Dover Chemistry | D5: Digital Outreach | E5: Instagram Post/Carousel | F5: Calcium Carbonate — CaCO₃ erosion & chalk geology | G5: ~200 impressions | H5: Carousel posted; engagement data captured | I5: Google Drive > RSC Evidence > Instagram_WCD | J5: 5 | K5: Jason | L5: Chemistry of Kent series — post 1
A6: E003 | B6: 2026-03-07 | C6: Blog Article — Pfizer Sandwich & Drug Synthesis | D6: Chemistry Communication | E6: Blog Article | F6: Pharmaceutical synthesis; Pfizer legacy in Kent | G6: Online readers | H6: Published to CATS website; 800+ word academic article | I6: Google Drive > RSC Evidence > Blog_Pfizer | J6: 5 | K6: Jason | L6: Post 4 of Chemistry of Kent series
A7: E004 | B7: 2026-03-08 | C7: PEEL Workshop — Member Writing Assessment | D7: Mentoring & Teaching | E7: Before/After Writing | F7: N/A — Writing Mechanics | G7: 10 | H7: 10 members; before/after drafts showing structured improvement | I7: Google Drive > RSC Evidence > PEEL_Workshop_Drafts | J7: 4 | K7: Jason | L7: Draft pairs archived for each member

Sheet 🎓 UCAS EVIDENCE SUMMARY
A1: UCAS EVIDENCE | Mentoring & Teaching Leadership Portfolio
A2: Use this sheet to curate the strongest evidence for UCAS PS narrative
A4: 🎯 HEADLINE CLAIM (for PS):
A5: For the leadership team, these statistics will be very useful for when you are writing your personal statement or your CV for your university application since these metrics are solid evidence for the impact we have made
A7: 📊 KEY QUANTITATIVE METRICS TO INCLUDE:
A8: Metric | B8: Target | C8: Actual (from Data) | D8: PS Use
A9: Total members mentored | B9: ≥20 | C9: =COUNTA('👥 MEMBER REGISTRY'!B4:B200) -> 23 | D9: Demonstrates scale of leadership
A10: Sessions delivered | B10: ≥6 | C10: ='📅 SESSION LOG'!B2 -> 14 | D10: Shows sustained programme
A11: Avg test score improvement | B11: ≥+15pp | C11: =IFERROR(AVERAGE('🧪 TEST SCORES'!L4:L200),"") -> 0.060406091 | D11: Proves learning gain; measurable teaching impact
A12: Avg post-test score | B12: ≥70% | C12: =IFERROR(AVERAGE('🧪 TEST SCORES'!K4:K200),"") -> 0.54833333 | D12: Absolute attainment benchmark
A13: Articles passing QA | B13: ≥15 | C13: =COUNTA('✍️ WRITING QUALITY'!O4:O200) -> 0 | D13: Rigorous output quality
A14: RSC evidence items logged | B14: ≥20 | C14: =COUNTA('🏆 RSC EVIDENCE LOG'!C4:C200) -> 4 | D14: Cross-validates with award submission
A15: Members showing >10pp improvement | B15: ≥75% of cohort | C15: =COUNTIF('🧪 TEST SCORES'!L4:L200,">0.1") -> 22 | D15: Strong cohort-level teaching effectiveness
